Workbook

Sheet demand_raw
A1: Date | B1: week_start_date | C1: trend_name | D1: trend_key | E1: search_index | F1: demand_tier | G1: apparel_type
A2: 44192 | B2: =A2+1 -> 44193 | C2: Oversized T-shirt | D2: =VLOOKUP(C2,trend_sales_map!$A$2:$B$5,2,) -> oversized_tshirt | E2: 4 | F2: mid | G2: tops
A3: 44199 | B3: =A3+1 -> 44200 | C3: Oversized T-shirt | D3: =VLOOKUP(C3,trend_sales_map!$A$2:$B$5,2,) -> oversized_tshirt | E3: 0 | F3: mid | G3: tops
A4: 44206 | B4: =A4+1 -> 44207 | C4: Oversized T-shirt | D4: =VLOOKUP(C4,trend_sales_map!$A$2:$B$5,2,) -> oversized_tshirt | E4: 4 | F4: mid | G4: tops
A5: 44213 | B5: =A5+1 -> 44214 | C5: Oversized T-shirt | D5: =VLOOKUP(C5,trend_sales_map!$A$2:$B$5,2,) -> oversized_tshirt | E5: 0 | F5: mid | G5: tops
A6: 44220 | B6: =A6+1 -> 44221 | C6: Oversized T-shirt | D6: =VLOOKUP(C6,trend_sales_map!$A$2:$B$5,2,) -> oversized_tshirt | E6: 5 | F6: mid | G6: tops
A7: 44227 | B7: =A7+1 -> 44228 | C7: Oversized T-shirt | D7: =VLOOKUP(C7,trend_sales_map!$A$2:$B$5,2,) -> oversized_tshirt | E7: 4 | F7: mid | G7: tops
A8: 44234 | B8: =A8+1 -> 44235 | C8: Oversized T-shirt | D8: =VLOOKUP(C8,trend_sales_map!$A$2:$B$5,2,) -> oversized_tshirt | E8: 4 | F8: mid | G8: tops
A9: 44241 | B9: =A9+1 -> 44242 | C9: Oversized T-shirt | D9: =VLOOKUP(C9,trend_sales_map!$A$2:$B$5,2,) -> oversized_tshirt | E9: 4 | F9: mid | G9: tops
A10: 44248 | B10: =A10+1 -> 44249 | C10: Oversized T-shirt | D10: =VLOOKUP(C10,trend_sales_map!$A$2:$B$5,2,) -> oversized_tshirt | E10: 5 | F10: mid | G10: tops
A11: 44255 | B11: =A11+1 -> 44256 | C11: Oversized T-shirt | D11: =VLOOKUP(C11,trend_sales_map!$A$2:$B$5,2,) -> oversized_tshirt | E11: 7 | F11: mid | G11: tops
A12: 44262 | B12: =A12+1 -> 44263 | C12: Oversized T-shirt | D12: =VLOOKUP(C12,trend_sales_map!$A$2:$B$5,2,) -> oversized_tshirt | E12: 4 | F12: mid | G12: tops
A13: 44269 | B13: =A13+1 -> 44270 | C13: Oversized T-shirt | D13: =VLOOKUP(C13,trend_sales_map!$A$2:$B$5,2,) -> oversized_tshirt | E13: 7 | F13: mid | G13: tops
... A1049: 46019 | B1049: =A1049+1 -> 46020 | C1049: Co-ord Set | D1049: =VLOOKUP(C1049,trend_sales_map!$A$2:$B$5,2,) -> coord_set | E1049: 36 | F1049: low | G1049: outfit

Sheet sales_raw
A1: saleID | B1: saleDate | C1: week_start_date | D1: productID | E1: productName | F1: productCategory | G1: productColor | H1: productSize | I1: quantity | J1: unitPrice | K1: costPrice | L1: totalAmount | M1: totalCost | N1: customerID | O1: customerName | P1: location | Q1: locationLatitude | R1: locationLongitude | S1: salespersonID | T1: salespersonName | U1: status | V1: salesChannel
A2: S00001 | B2: 45170.905 | C2: =INT(B2) - WEEKDAY(INT(B2), 2) + 1 -> 45166 | D2: P1000 | E2: Women's_000 | F2: Women's Dresses | G2: Red | H2: XXL | I2: 2 | J2: 1572.76 | K2: 1154.01 | L2: 3145.52 | M2: 2308.02 | N2: C20000 | O2: Vishal_0000 | P2: Tiruchirappalli | Q2: 10.7905 | R2: 78.7047 | S2: SP114 | T2: Salesperson_14 | U2: Pending | V2: online
A3: S00002 | B3: 44991.639 | C3: =INT(B3) - WEEKDAY(INT(B3), 2) + 1 -> 44991 | D3: P1001 | E3: Women's_001 | F3: Women's Dresses | G3: Maroon | H3: XS | I3: 1 | J3: 247.34 | K3: 220.37 | L3: 247.34 | M3: 220.37 | N3: C20001 | O3: Sathish_0001 | P3: Erode | Q3: 11.34 | R3: 77.7172 | S3: SP102 | T3: Salesperson_2 | U3: Paid | V3: online
A4: S00003 | B4: 45468.507 | C4: =INT(B4) - WEEKDAY(INT(B4), 2) + 1 -> 45467 | D4: P1002 | E4: Women's_002 | F4: Women's Dresses | G4: Black | H4: S | I4: 2 | J4: 1620.21 | K4: 1269.43 | L4: 3240.42 | M4: 2538.86 | N4: C20002 | O4: Anu_0002 | P4: Chennai | Q4: 13.0827 | R4: 80.2707 | S4: SP135 | T4: Salesperson_35 | U4: Pending | V4: in-store
A5: S00004 | B5: 44931.438 | C5: =INT(B5) - WEEKDAY(INT(B5), 2) + 1 -> 44928 | D5: P1003 | E5: Kurta_003 | F5: Kurta | G5: Black | H5: L | I5: 4 | J5: 520.84 | K5: 358.15 | L5: 2083.36 | M5: 1432.6 | N5: C20003 | O5: Sathish_0003 | P5: Salem | Q5: 11.6643 | R5: 78.146 | S5: SP100 | T5: Salesperson_0 | U5: Pending | V5: in-store
A6: S00005 | B6: 45165.658 | C6: =INT(B6) - WEEKDAY(INT(B6), 2) + 1 -> 45159 | D6: P1004 | E6: Kurta_004 | F6: Kurta | G6: Yellow | H6: M | I6: 1 | J6: 1079.66 | K6: 966.26 | L6: 1079.66 | M6: 966.26 | N6: C20004 | O6: Kavin_0004 | P6: Tiruchirappalli | Q6: 10.7905 | R6: 78.7047 | S6: SP148 | T6: Salesperson_48 | U6: Returned | V6: in-store
A7: S00006 | B7: 45230.861 | C7: =INT(B7) - WEEKDAY(INT(B7), 2) + 1 -> 45229 | D7: P1005 | E7: Women's_005 | F7: Women's Dresses | G7: Blue | H7: L | I7: 1 | J7: 349.62 | K7: 309.3 | L7: 349.62 | M7: 309.3 | N7: C20005 | O7: Diya_0005 | P7: Tirunelveli | Q7: 8.7139 | R7: 77.7567 | S7: SP122 | T7: Salesperson_22 | U7: Cancelled | V7: mobile_app
A8: S00007 | B8: 45554.804 | C8: =INT(B8) - WEEKDAY(INT(B8), 2) + 1 -> 45551 | D8: P1006 | E8: T-Shirts_006 | F8: T-Shirts | G8: Red | H8: XXL | I8: 2 | J8: 731.06 | K8: 491.5 | L8: 1462.12 | M8: 983 | N8: C20006 | O8: Ravi_0006 | P8: Coimbatore | Q8: 11.0168 | R8: 76.9558 | S8: SP124 | T8: Salesperson_24 | U8: Paid | V8: in-store
A9: S00008 | B9: 45371.742 | C9: =INT(B9) - WEEKDAY(INT(B9), 2) + 1 -> 45369 | D9: P1007 | E9: T-Shirts_007 | F9: T-Shirts | G9: Yellow | H9: XL | I9: 1 | J9: 2291.44 | K9: 1552.76 | L9: 2291.44 | M9: 1552.76 | N9: C20007 | O9: Meena_0007 | P9: Coimbatore | Q9: 11.0168 | R9: 76.9558 | S9: SP102 | T9: Salesperson_2 | U9: Pending | V9: in-store
A10: S00009 | B10: 45357.563 | C10: =INT(B10) - WEEKDAY(INT(B10), 2) + 1 -> 45355 | D10: P1008 | E10: T-Shirts_008 | F10: T-Shirts | G10: Blue | H10: S | I10: 1 | J10: 1505.71 | K10: 917.57 | L10: 1505.71 | M10: 917.57 | N10: C20008 | O10: Bhuvana_0008 | P10: Coimbatore | Q10: 11.0168 | R10: 76.9558 | S10: SP124 | T10: Salesperson_24 | U10: Returned | V10: mobile_app
A11: S00010 | B11: 45474.641 | C11: =INT(B11) - WEEKDAY(INT(B11), 2) + 1 -> 45474 | D11: P1009 | E11: Sportswear_009 | F11: Sportswear | G11: Yellow | H11: S | I11: 2 | J11: 1575.17 | K11: 1380.73 | L11: 3150.34 | M11: 2761.46 | N11: C20009 | O11: Karthik_0009 | P11: Tirunelveli | Q11: 8.7139 | R11: 77.7567 | S11: SP113 | T11: Salesperson_13 | U11: Returned | V11: mobile_app
A12: S00011 | B12: 44984.501 | C12: =INT(B12) - WEEKDAY(INT(B12), 2) + 1 -> 44984 | D12: P1010 | E12: Women's_010 | F12: Women's Dresses | G12: Green | H12: XL | I12: 2 | J12: 1093.96 | K12: 745.43 | L12: 2187.92 | M12: 1490.86 | N12: C20010 | O12: Devi_0010 | P12: Tiruchirappalli | Q12: 10.7905 | R12: 78.7047 | S12: SP110 | T12: Salesperson_10 | U12: Shipped | V12: in-store
A13: S00012 | B13: 45465.594 | C13: =INT(B13) - WEEKDAY(INT(B13), 2) + 1 -> 45460 | D13: P1011 | E13: Kurta_011 | F13: Kurta | G13: White | H13: XXL | I13: 2 | J13: 834.8 | K13: 575.08 | L13: 1669.6 | M13: 1150.16 | N13: C20011 | O13: Devi_0011 | P13: Tiruchirappalli | Q13: 10.7905 | R13: 78.7047 | S13: SP143 | T13: Salesperson_43 | U13: Returned | V13: online
... A10001: S10000 | B10001: 45291.661 | C10001: =INT(B10001) - WEEKDAY(INT(B10001), 2) + 1 -> 45285 | D10001: P1499 | E10001: Kid's_499 | F10001: Kid's Wear | G10001: Maroon | H10001: XL | I10001: 1 | J10001: 901.34 | K10001: 571.44 | L10001: 901.34 | M10001: 571.44 | N10001: C29999 | O10001: Karthik_9999 | P10001: Salem | Q10001: 11.6643 | R10001: 78.146 | S10001: SP128 | T10001: Salesperson_28 | U10001: Paid | V10001: in-store

Sheet sales_weekly_agg
A3: Sum of quantity | B3: Column Labels
A4: Row Labels | B4: Jeans | C4: Kid's Wear | D4: Kurta | E4: Men's Shirts | F4: Sarees | G4: Sportswear | H4: T-Shirts | I4: Women's Dresses | J4: Grand Total
A5: 44921 | B5: 3 | E5: 4 | F5: 9 | H5: 1 | I5: 8 | J5: 25
A6: 44928 | B6: 19 | C6: 26 | D6: 24 | E6: 28 | F6: 30 | G6: 25 | H6: 26 | I6: 33 | J6: 211
A7: 44935 | B7: 19 | C7: 32 | D7: 25 | E7: 19 | F7: 29 | G7: 38 | H7: 17 | I7: 34 | J7: 213
A8: 44942 | B8: 27 | C8: 27 | D8: 28 | E8: 32 | F8: 28 | G8: 20 | H8: 22 | I8: 36 | J8: 220
A9: 44949 | B9: 35 | C9: 26 | D9: 30 | E9: 24 | F9: 14 | G9: 33 | H9: 40 | I9: 26 | J9: 228
A10: 44956 | B10: 35 | C10: 38 | D10: 40 | E10: 17 | F10: 33 | G10: 27 | H10: 22 | I10: 18 | J10: 230
A11: 44963 | B11: 31 | C11: 17 | D11: 10 | E11: 23 | F11: 21 | G11: 28 | H11: 20 | I11: 27 | J11: 177
A12: 44970 | B12: 31 | C12: 16 | D12: 13 | E12: 27 | F12: 21 | G12: 19 | H12: 23 | I12: 20 | J12: 170
A13: 44977 | B13: 37 | C13: 19 | D13: 19 | E13: 30 | F13: 18 | G13: 28 | H13: 42 | I13: 16 | J13: 209
A14: 44984 | B14: 29 | C14: 21 | D14: 37 | E14: 19 | F14: 18 | G14: 31 | H14: 38 | I14: 26 | J14: 219
A15: 44991 | B15: 33 | C15: 33 | D15: 20 | E15: 22 | F15: 30 | G15: 21 | H15: 36 | I15: 21 | J15: 216
A16: 44998 | B16: 31 | C16: 22 | D16: 24 | E16: 26 | F16: 26 | G16: 34 | H16: 31 | I16: 26 | J16: 220
A17: 45005 | B17: 21 | C17: 22 | D17: 37 | E17: 38 | F17: 36 | G17: 29 | H17: 15 | I17: 17 | J17: 215
... A98: 45572 | B98: 22 | C98: 15 | D98: 40 | E98: 12 | F98: 25 | G98: 31 | H98: 42 | I98: 12 | J98: 199
A99: Grand Total | B99: 2560 | C99: 2403 | D99: 2569 | E99: 2456 | F99: 2501 | G99: 2599 | H99: 2569 | I99: 2392 | J99: 20049

Sheet trend_sales_map
A1: trend_name | B1: trend_key | C1: sales_category | D1: mapping_strength
A2: Oversized T-shirt | B2: oversized_tshirt | C2: T-Shirts | D2: strong
A3: Cargo Pants | B3: cargo_pants | C3: Jeans | D3: medium
A4: Sportswear | B4: sportswear | C4: Sportswear | D4: strong
A5: Co-ord Set | B5: coord_set | C5: Women's Dresses | D5: weak

Sheet sportswear_dvs
A1: week_start_date | B1: demand_index | C1: demand_lag1 | D1: demand_lag2 | E1: demand_lag3 | F1: units_sold | G1: gap | H1: gap_sign | I1: same_as_last_week | J1: run_length
A2: 44193 | B2: 27 | F2: =_xlfn.IFNA(VLOOKUP(A2,sales_weekly_agg!$A$5:$G$98,7,),"") | G2: =IF(F2="","",F2-B2) | K2: Correlation (Lag 1) | L2: =CORREL(C:C,F:F) -> 0.10223271
A3: 44200 | B3: 28 | C3: =B2 -> 27 | F3: =_xlfn.IFNA(VLOOKUP(A3,sales_weekly_agg!$A$5:$G$98,7,),"") | G3: =IF(F3="","",F3-B3) | K3: Correlation (Lag 2) | L3: =CORREL(D:D,F:F) -> 0.02563782
A4: 44207 | B4: 26 | C4: =B3 -> 28 | D4: =B2 -> 27 | F4: =_xlfn.IFNA(VLOOKUP(A4,sales_weekly_agg!$A$5:$G$98,7,),"") | G4: =IF(F4="","",F4-B4) | K4: Correlation (Lag 3) | L4: =CORREL(E:E,F:F) -> -0.058387082
A5: 44214 | B5: 28 | C5: =B4 -> 26 | D5: =B3 -> 28 | E5: =B2 -> 27 | F5: =_xlfn.IFNA(VLOOKUP(A5,sales_weekly_agg!$A$5:$G$98,7,),"") | G5: =IF(F5="","",F5-B5)
A6: 44221 | B6: 30 | C6: =B5 -> 28 | D6: =B4 -> 26 | E6: =B3 -> 28 | F6: =_xlfn.IFNA(VLOOKUP(A6,sales_weekly_agg!$A$5:$G$98,7,),"") | G6: =IF(F6="","",F6-B6) | K6: Demand Volatility | L6: =_xlfn.STDEV.S(B106:B199) -> 2.5288317
A7: 44228 | B7: 28 | C7: =B6 -> 30 | D7: =B5 -> 28 | E7: =B4 -> 26 | F7: =_xlfn.IFNA(VLOOKUP(A7,sales_weekly_agg!$A$5:$G$98,7,),"") | G7: =IF(F7="","",F7-B7) | K7: Sales Volatility | L7: =_xlfn.STDEV.S(F106:F199) -> 8.4391655
A8: 44235 | B8: 27 | C8: =B7 -> 28 | D8: =B6 -> 30 | E8: =B5 -> 28 | F8: =_xlfn.IFNA(VLOOKUP(A8,sales_weekly_agg!$A$5:$G$98,7,),"") | G8: =IF(F8="","",F8-B8) | K8: S-D Volatility Ratio | L8: =L7/L6 -> 3.3371796
A9: 44242 | B9: 24 | C9: =B8 -> 27 | D9: =B7 -> 28 | E9: =B6 -> 30 | F9: =_xlfn.IFNA(VLOOKUP(A9,sales_weekly_agg!$A$5:$G$98,7,),"") | G9: =IF(F9="","",F9-B9) | K9: Persistence % | L9: =AVERAGE(I107:I199) -> 0.4516129
A10: 44249 | B10: 27 | C10: =B9 -> 24 | D10: =B8 -> 27 | E10: =B7 -> 28 | F10: =_xlfn.IFNA(VLOOKUP(A10,sales_weekly_agg!$A$5:$G$98,7,),"") | G10: =IF(F10="","",F10-B10) | K10: max run length | L10: =MAX(J107:J199) -> 13
A11: 44256 | B11: 27 | C11: =B10 -> 27 | D11: =B9 -> 24 | E11: =B8 -> 27 | F11: =_xlfn.IFNA(VLOOKUP(A11,sales_weekly_agg!$A$5:$G$98,7,),"") | G11: =IF(F11="","",F11-B11) | K11: dominant gap sign | L11: =_xlfn.MODE.SNGL(H106:H199) -> -1
A12: 44263 | B12: 29 | C12: =B11 -> 27 | D12: =B10 -> 27 | E12: =B9 -> 24 | F12: =_xlfn.IFNA(VLOOKUP(A12,sales_weekly_agg!$A$5:$G$98,7,),"") | G12: =IF(F12="","",F12-B12)
A13: 44270 | B13: 27 | C13: =B12 -> 29 | D13: =B11 -> 27 | E13: =B10 -> 27 | F13: =_xlfn.IFNA(VLOOKUP(A13,sales_weekly_agg!$A$5:$G$98,7,),"") | G13: =IF(F13="","",F13-B13)
A14: 44277 | B14: 29 | C14: =B13 -> 27 | D14: =B12 -> 29 | E14: =B11 -> 27 | F14: =_xlfn.IFNA(VLOOKUP(A14,sales_weekly_agg!$A$5:$G$98,7,),"") | G14: =IF(F14="","",F14-B14)
A15: 44284 | B15: 27 | C15: =B14 -> 29 | D15: =B13 -> 27 | E15: =B12 -> 29 | F15: =_xlfn.IFNA(VLOOKUP(A15,sales_weekly_agg!$A$5:$G$98,7,),"") | G15: =IF(F15="","",F15-B15)
A16: 44291 | B16: 25 | C16: =B15 -> 27 | D16: =B14 -> 29 | E16: =B13 -> 27 | F16: =_xlfn.IFNA(VLOOKUP(A16,sales_weekly_agg!$A$5:$G$98,7,),"") | G16: =IF(F16="","",F16-B16)
A17: 44298 | B17: 22 | C17: =B16 -> 25 | D17: =B15 -> 27 | E17: =B14 -> 29 | F17: =_xlfn.IFNA(VLOOKUP(A17,sales_weekly_agg!$A$5:$G$98,7,),"") | G17: =IF(F17="","",F17-B17)
A18: 44305 | B18: 20 | C18: =B17 -> 22 | D18: =B16 -> 25 | E18: =B15 -> 27 | F18: =_xlfn.IFNA(VLOOKUP(A18,sales_weekly_agg!$A$5:$G$98,7,),"") | G18: =IF(F18="","",F18-B18)
A19: 44312 | B19: 19 | C19: =B18 -> 20 | D19: =B17 -> 22 | E19: =B16 -> 25 | F19: =_xlfn.IFNA(VLOOKUP(A19,sales_weekly_agg!$A$5:$G$98,7,),"") | G19: =IF(F19="","",F19-B19)
A20: 44319 | B20: 21 | C20: =B19 -> 19 | D20: =B18 -> 20 | E20: =B17 -> 22 | F20: =_xlfn.IFNA(VLOOKUP(A20,sales_weekly_agg!$A$5:$G$98,7,),"") | G20: =IF(F20="","",F20-B20)
A21: 44326 | B21: 23 | C21: =B20 -> 21 | D21: =B19 -> 19 | E21: =B18 -> 20 | F21: =_xlfn.IFNA(VLOOKUP(A21,sales_weekly_agg!$A$5:$G$98,7,),"") | G21: =IF(F21="","",F21-B21)
A22: 44333 | B22: 22 | C22: =B21 -> 23 | D22: =B20 -> 21 | E22: =B19 -> 19 | F22: =_xlfn.IFNA(VLOOKUP(A22,sales_weekly_agg!$A$5:$G$98,7,),"") | G22: =IF(F22="","",F22-B22)
A23: 44340 | B23: 24 | C23: =B22 -> 22 | D23: =B21 -> 23 | E23: =B20 -> 21 | F23: =_xlfn.IFNA(VLOOKUP(A23,sales_weekly_agg!$A$5:$G$98,7,),"") | G23: =IF(F23="","",F23-B23)
... A105: 44914 | B105: 29 | C105: =B104 -> 29 | D105: =B103 -> 27 | E105: =B102 -> 29 | F105: =_xlfn.IFNA(VLOOKUP(A105,sales_weekly_agg!$A$5:$G$98,7,),"") | G105: =IF(F105="","",F105-B105)
A106: 44921 | B106: 28 | C106: =B105 -> 29 | D106: =B104 -> 29 | E106: =B103 -> 27 | F106: =_xlfn.IFNA(VLOOKUP(A106,sales_weekly_agg!$A$5:$G$98,7,),"") -> 0 | G106: =IF(F106="","",F106-B106) -> -28 | H106: =_xlfn.IFS(G106>0,1,G106<0,-1,G106 = 0,0) -> -1
A107: 44928 | B107: 29 | C107: =B106 -> 28 | D107: =B105 -> 29 | E107: =B104 -> 29 | F107: =_xlfn.IFNA(VLOOKUP(A107,sales_weekly_agg!$A$5:$G$98,7,),"") -> 25 | G107: =IF(F107="","",F107-B107) -> -4 | H107: =_xlfn.IFS(G107>0,1,G107<0,-1,G107 = 0,0) -> -1 | I107: =IF(H107=H106,1,0) -> 1 | J107: 1
A108: 44935 | B108: 28 | C108: =B107 -> 29 | D108: =B106 -> 28 | E108: =B105 -> 29 | F108: =_xlfn.IFNA(VLOOKUP(A108,sales_weekly_agg!$A$5:$G$98,7,),"") -> 38 | G108: =IF(F108="","",F108-B108) -> 10 | H108: =_xlfn.IFS(G108>0,1,G108<0,-1,G108 = 0,0) -> 1 | I108: =IF(H108=H107,1,0) -> 0 | J108: =IF(I107=I108,J107+1,1) -> 1
A109: 44942 | B109: 28 | C109: =B108 -> 28 | D109: =B107 -> 29 | E109: =B106 -> 28 | F109: =_xlfn.IFNA(VLOOKUP(A109,sales_weekly_agg!$A$5:$G$98,7,),"") -> 20 | G109: =IF(F109="","",F109-B109) -> -8 | H109: =_xlfn.IFS(G109>0,1,G109<0,-1,G109 = 0,0) -> -1 | I109: =IF(H109=H108,1,0) -> 0 | J109: =IF(I108=I109,J108+1,1) -> 2
A110: 44949 | B110: 28 | C110: =B109 -> 28 | D110: =B108 -> 28 | E110: =B107 -> 29 | F110: =_xlfn.IFNA(VLOOKUP(A110,sales_weekly_agg!$A$5:$G$98,7,),"") -> 33 | G110: =IF(F110="","",F110-B110) -> 5 | H110: =_xlfn.IFS(G110>0,1,G110<0,-1,G110 = 0,0) -> 1 | I110: =IF(H110=H109,1,0) -> 0 | J110: =IF(I109=I110,J109+1,1) -> 3
A111: 44956 | B111: 27 | C111: =B110 -> 28 | D111: =B109 -> 28 | E111: =B108 -> 28 | F111: =_xlfn.IFNA(VLOOKUP(A111,sales_weekly_agg!$A$5:$G$98,7,),"") -> 27 | G111: =IF(F111="","",F111-B111) -> 0 | H111: =_xlfn.IFS(G111>0,1,G111<0,-1,G111 = 0,0) -> 0 | I111: =IF(H111=H110,1,0) -> 0 | J111: =IF(I110=I111,J110+1,1) -> 4
A112: 44963 | B112: 26 | C112: =B111 -> 27 | D112: =B110 -> 28 | E112: =B109 -> 28 | F112: =_xlfn.IFNA(VLOOKUP(A112,sales_weekly_agg!$A$5:$G$98,7,),"") -> 28 | G112: =IF(F112="","",F112-B112) -> 2 | H112: =_xlfn.IFS(G112>0,1,G112<0,-1,G112 = 0,0) -> 1 | I112: =IF(H112=H111,1,0) -> 0 | J112: =IF(I111=I112,J111+1,1) -> 5
A113: 44970 | B113: 25 | C113: =B112 -> 26 | D113: =B111 -> 27 | E113: =B110 -> 28 | F113: =_xlfn.IFNA(VLOOKUP(A113,sales_weekly_agg!$A$5:$G$98,7,),"") -> 19 | G113: =IF(F113="","",F113-B113) -> -6 | H113: =_xlfn.IFS(G113>0,1,G113<0,-1,G113 = 0,0) -> -1 | I113: =IF(H113=H112,1,0) -> 0 | J113: =IF(I112=I113,J112+1,1) -> 6
A114: 44977 | B114: 28 | C114: =B113 -> 25 | D114: =B112 -> 26 | E114: =B111 -> 27 | F114: =_xlfn.IFNA(VLOOKUP(A114,sales_weekly_agg!$A$5:$G$98,7,),"") -> 28 | G114: =IF(F114="","",F114-B114) -> 0 | H114: =_xlfn.IFS(G114>0,1,G114<0,-1,G114 = 0,0) -> 0 | I114: =IF(H114=H113,1,0) -> 0 | J114: =IF(I113=I114,J113+1,1) -> 7
A115: 44984 | B115: 29 | C115: =B114 -> 28 | D115: =B113 -> 25 | E115: =B112 -> 26 | F115: =_xlfn.IFNA(VLOOKUP(A115,sales_weekly_agg!$A$5:$G$98,7,),"") -> 31 | G115: =IF(F115="","",F115-B115) -> 2 | H115: =_xlfn.IFS(G115>0,1,G115<0,-1,G115 = 0,0) -> 1 | I115: =IF(H115=H114,1,0) -> 0 | J115: =IF(I114=I115,J114+1,1) -> 8
A116: 44991 | B116: 30 | C116: =B115 -> 29 | D116: =B114 -> 28 | E116: =B113 -> 25 | F116: =_xlfn.IFNA(VLOOKUP(A116,sales_weekly_agg!$A$5:$G$98,7,),"") -> 21 | G116: =IF(F116="","",F116-B116) -> -9 | H116: =_xlfn.IFS(G116>0,1,G116<0,-1,G116 = 0,0) -> -1 | I116: =IF(H116=H115,1,0) -> 0 | J116: =IF(I115=I116,J115+1,1) -> 9
A117: 44998 | B117: 29 | C117: =B116 -> 30 | D117: =B115 -> 29 | E117: =B114 -> 28 | F117: =_xlfn.IFNA(VLOOKUP(A117,sales_weekly_agg!$A$5:$G$98,7,),"") -> 34 | G117: =IF(F117="","",F117-B117) -> 5 | H117: =_xlfn.IFS(G117>0,1,G117<0,-1,G117 = 0,0) -> 1 | I117: =IF(H117=H116,1,0) -> 0 | J117: =IF(I116=I117,J116+1,1) -> 10
A118: 45005 | B118: 29 | C118: =B117 -> 29 | D118: =B116 -> 30 | E118: =B115 -> 29 | F118: =_xlfn.IFNA(VLOOKUP(A118,sales_weekly_agg!$A$5:$G$98,7,),"") -> 29 | G118: =IF(F118="","",F118-B118) -> 0 | H118: =_xlfn.IFS(G118>0,1,G118<0,-1,G118 = 0,0) -> 0 | I118: =IF(H118=H117,1,0) -> 0 | J118: =IF(I117=I118,J117+1,1) -> 11
A119: 45012 | B119: 29 | C119: =B118 -> 29 | D119: =B117 -> 29 | E119: =B116 -> 30 | F119: =_xlfn.IFNA(VLOOKUP(A119,sales_weekly_agg!$A$5:$G$98,7,),"") -> 15 | G119: =IF(F119="","",F119-B119) -> -14 | H119: =_xlfn.IFS(G119>0,1,G119<0,-1,G119 = 0,0) -> -1 | I119: =IF(H119=H118,1,0) -> 0 | J119: =IF(I118=I119,J118+1,1) -> 12
... A199: 45572 | B199: 31 | C199: =B198 -> 34 | D199: =B197 -> 32 | E199: =B196 -> 29 | F199: =_xlfn.IFNA(VLOOKUP(A199,sales_weekly_agg!$A$5:$G$98,7,),"") -> 31 | G199: =IF(F199="","",F199-B199) -> 0 | H199: =_xlfn.IFS(G199>0,1,G199<0,-1,G199 = 0,0) -> 0 | I199: =IF(H199=H198,1,0) -> 0 | J199: =IF(I198=I199,J198+1,1) -> 1
A200: 45579 | B200: 31 | C200: =B199 -> 31 | D200: =B198 -> 34 | E200: =B197 -> 32 | F200: =_xlfn.IFNA(VLOOKUP(A200,sales_weekly_agg!$A$5:$G$98,7,),"") | G200: =IF(F200="","",F200-B200)
...

Sheet cargo_dvs
A1: week_start_date | B1: demand_index | C1: units_sold | D1: gap | E1: gap_sign | F1: same_as_last_week | G1: run_length
A2: 44193 | B2: 14 | C2: =_xlfn.IFNA(VLOOKUP(A2,sales_weekly_agg!$A$5:$B$98,2,FALSE),"") | D2: =IF(C2="","",C2-B2)
A3: 44200 | B3: 14 | C3: =_xlfn.IFNA(VLOOKUP(A3,sales_weekly_agg!$A$5:$B$98,2,FALSE),"") | D3: =IF(C3="","",C3-B3) | I3: Persistence % | J3: =AVERAGE(F107:F199) -> 1
A4: 44207 | B4: 13 | C4: =_xlfn.IFNA(VLOOKUP(A4,sales_weekly_agg!$A$5:$B$98,2,FALSE),"") | D4: =IF(C4="","",C4-B4) | I4: max run length | J4: =MAX(G107:G199) -> 93
A5: 44214 | B5: 14 | C5: =_xlfn.IFNA(VLOOKUP(A5,sales_weekly_agg!$A$5:$B$98,2,FALSE),"") | D5: =IF(C5="","",C5-B5) | I5: dominant gap sign | J5: =_xlfn.MODE.SNGL(E106:E199) -> -1
A6: 44221 | B6: 14 | C6: =_xlfn.IFNA(VLOOKUP(A6,sales_weekly_agg!$A$5:$B$98,2,FALSE),"") | D6: =IF(C6="","",C6-B6)
A7: 44228 | B7: 14 | C7: =_xlfn.IFNA(VLOOKUP(A7,sales_weekly_agg!$A$5:$B$98,2,FALSE),"") | D7: =IF(C7="","",C7-B7)
A8: 44235 | B8: 13 | C8: =_xlfn.IFNA(VLOOKUP(A8,sales_weekly_agg!$A$5:$B$98,2,FALSE),"") | D8: =IF(C8="","",C8-B8)
A9: 44242 | B9: 12 | C9: =_xlfn.IFNA(VLOOKUP(A9,sales_weekly_agg!$A$5:$B$98,2,FALSE),"") | D9: =IF(C9="","",C9-B9)
A10: 44249 | B10: 15 | C10: =_xlfn.IFNA(VLOOKUP(A10,sales_weekly_agg!$A$5:$B$98,2,FALSE),"") | D10: =IF(C10="","",C10-B10)
A11: 44256 | B11: 14 | C11: =_xlfn.IFNA(VLOOKUP(A11,sales_weekly_agg!$A$5:$B$98,2,FALSE),"") | D11: =IF(C11="","",C11-B11)
A12: 44263 | B12: 14 | C12: =_xlfn.IFNA(VLOOKUP(A12,sales_weekly_agg!$A$5:$B$98,2,FALSE),"") | D12: =IF(C12="","",C12-B12)
A13: 44270 | B13: 14 | C13: =_xlfn.IFNA(VLOOKUP(A13,sales_weekly_agg!$A$5:$B$98,2,FALSE),"") | D13: =IF(C13="","",C13-B13)
A14: 44277 | B14: 14 | C14: =_xlfn.IFNA(VLOOKUP(A14,sales_weekly_agg!$A$5:$B$98,2,FALSE),"") | D14: =IF(C14="","",C14-B14)
A15: 44284 | B15: 17 | C15: =_xlfn.IFNA(VLOOKUP(A15,sales_weekly_agg!$A$5:$B$98,2,FALSE),"") | D15: =IF(C15="","",C15-B15)
A16: 44291 | B16: 16 | C16: =_xlfn.IFNA(VLOOKUP(A16,sales_weekly_agg!$A$5:$B$98,2,FALSE),"") | D16: =IF(C16="","",C16-B16)
A17: 44298 | B17: 15 | C17: =_xlfn.IFNA(VLOOKUP(A17,sales_weekly_agg!$A$5:$B$98,2,FALSE),"") | D17: =IF(C17="","",C17-B17)
... A105: 44914 | B105: 36 | C105: =_xlfn.IFNA(VLOOKUP(A105,sales_weekly_agg!$A$5:$B$98,2,FALSE),"") | D105: =IF(C105="","",C105-B105)
A106: 44921 | B106: 38 | C106: =_xlfn.IFNA(VLOOKUP(A106,sales_weekly_agg!$A$5:$B$98,2,FALSE),"") -> 3 | D106: =IF(C106="","",C106-B106) -> -35 | E106: =_xlfn.IFS(D106>0,1,D106<0,-1,D106=0,0) -> -1
A107: 44928 | B107: 37 | C107: =_xlfn.IFNA(VLOOKUP(A107,sales_weekly_agg!$A$5:$B$98,2,FALSE),"") -> 19 | D107: =IF(C107="","",C107-B107) -> -18 | E107: =_xlfn.IFS(D107>0,1,D107<0,-1,D107=0,0) -> -1 | F107: =IF(E106=E107,1,0) -> 1 | G107: 1
A108: 44935 | B108: 40 | C108: =_xlfn.IFNA(VLOOKUP(A108,sales_weekly_agg!$A$5:$B$98,2,FALSE),"") -> 19 | D108: =IF(C108="","",C108-B108) -> -21 | E108: =_xlfn.IFS(D108>0,1,D108<0,-1,D108=0,0) -> -1 | F108: =IF(E107=E108,1,0) -> 1 | G108: =IF(F107=F108,G107+1,1) -> 2
A109: 44942 | B109: 38 | C109: =_xlfn.IFNA(VLOOKUP(A109,sales_weekly_agg!$A$5:$B$98,2,FALSE),"") -> 27 | D109: =IF(C109="","",C109-B109) -> -11 | E109: =_xlfn.IFS(D109>0,1,D109<0,-1,D109=0,0) -> -1 | F109: =IF(E108=E109,1,0) -> 1 | G109: =IF(F108=F109,G108+1,1) -> 3
A110: 44949 | B110: 43 | C110: =_xlfn.IFNA(VLOOKUP(A110,sales_weekly_agg!$A$5:$B$98,2,FALSE),"") -> 35 | D110: =IF(C110="","",C110-B110) -> -8 | E110: =_xlfn.IFS(D110>0,1,D110<0,-1,D110=0,0) -> -1 | F110: =IF(E109=E110,1,0) -> 1 | G110: =IF(F109=F110,G109+1,1) -> 4
A111: 44956 | B111: 41 | C111: =_xlfn.IFNA(VLOOKUP(A111,sales_weekly_agg!$A$5:$B$98,2,FALSE),"") -> 35 | D111: =IF(C111="","",C111-B111) -> -6 | E111: =_xlfn.IFS(D111>0,1,D111<0,-1,D111=0,0) -> -1 | F111: =IF(E110=E111,1,0) -> 1 | G111: =IF(F110=F111,G110+1,1) -> 5
A112: 44963 | B112: 43 | C112: =_xlfn.IFNA(VLOOKUP(A112,sales_weekly_agg!$A$5:$B$98,2,FALSE),"") -> 31 | D112: =IF(C112="","",C112-B112) -> -12 | E112: =_xlfn.IFS(D112>0,1,D112<0,-1,D112=0,0) -> -1 | F112: =IF(E111=E112,1,0) -> 1 | G112: =IF(F111=F112,G111+1,1) -> 6
A113: 44970 | B113: 43 | C113: =_xlfn.IFNA(VLOOKUP(A113,sales_weekly_agg!$A$5:$B$98,2,FALSE),"") -> 31 | D113: =IF(C113="","",C113-B113) -> -12 | E113: =_xlfn.IFS(D113>0,1,D113<0,-1,D113=0,0) -> -1 | F113: =IF(E112=E113,1,0) -> 1 | G113: =IF(F112=F113,G112+1,1) -> 7
A114: 44977 | B114: 49 | C114: =_xlfn.IFNA(VLOOKUP(A114,sales_weekly_agg!$A$5:$B$98,2,FALSE),"") -> 37 | D114: =IF(C114="","",C114-B114) -> -12 | E114: =_xlfn.IFS(D114>0,1,D114<0,-1,D114=0,0) -> -1 | F114: =IF(E113=E114,1,0) -> 1 | G114: =IF(F113=F114,G113+1,1) -> 8
A115: 44984 | B115: 45 | C115: =_xlfn.IFNA(VLOOKUP(A115,sales_weekly_agg!$A$5:$B$98,2,FALSE),"") -> 29 | D115: =IF(C115="","",C115-B115) -> -16 | E115: =_xlfn.IFS(D115>0,1,D115<0,-1,D115=0,0) -> -1 | F115: =IF(E114=E115,1,0) -> 1 | G115: =IF(F114=F115,G114+1,1) -> 9
A116: 44991 | B116: 48 | C116: =_xlfn.IFNA(VLOOKUP(A116,sales_weekly_agg!$A$5:$B$98,2,FALSE),"") -> 33 | D116: =IF(C116="","",C116-B116) -> -15 | E116: =_xlfn.IFS(D116>0,1,D116<0,-1,D116=0,0) -> -1 | F116: =IF(E115=E116,1,0) -> 1 | G116: =IF(F115=F116,G115+1,1) -> 10
A117: 44998 | B117: 46 | C117: =_xlfn.IFNA(VLOOKUP(A117,sales_weekly_agg!$A$5:$B$98,2,FALSE),"") -> 31 | D117: =IF(C117="","",C117-B117) -> -15 | E117: =_xlfn.IFS(D117>0,1,D117<0,-1,D117=0,0) -> -1 | F117: =IF(E116=E117,1,0) -> 1 | G117: =IF(F116=F117,G116+1,1) -> 11
A118: 45005 | B118: 50 | C118: =_xlfn.IFNA(VLOOKUP(A118,sales_weekly_agg!$A$5:$B$98,2,FALSE),"") -> 21 | D118: =IF(C118="","",C118-B118) -> -29 | E118: =_xlfn.IFS(D118>0,1,D118<0,-1,D118=0,0) -> -1 | F118: =IF(E117=E118,1,0) -> 1 | G118: =IF(F117=F118,G117+1,1) -> 12
A119: 45012 | B119: 50 | C119: =_xlfn.IFNA(VLOOKUP(A119,sales_weekly_agg!$A$5:$B$98,2,FALSE),"") -> 18 | D119: =IF(C119="","",C119-B119) -> -32 | E119: =_xlfn.IFS(D119>0,1,D119<0,-1,D119=0,0) -> -1 | F119: =IF(E118=E119,1,0) -> 1 | G119: =IF(F118=F119,G118+1,1) -> 13
... A199: 45572 | B199: 68 | C199: =_xlfn.IFNA(VLOOKUP(A199,sales_weekly_agg!$A$5:$B$98,2,FALSE),"") -> 22 | D199: =IF(C199="","",C199-B199) -> -46 | E199: =_xlfn.IFS(D199>0,1,D199<0,-1,D199=0,0) -> -1 | F199: =IF(E198=E199,1,0) -> 1 | G199: =IF(F198=F199,G198+1,1) -> 93
A200: 45579 | B200: 60 | C200: =_xlfn.IFNA(VLOOKUP(A200,sales_weekly_agg!$A$5:$B$98,2,FALSE),"") | D200: =IF(C200="","",C200-B200)
A201: 45586 | B201: 64 | C201: =_xlfn.IFNA(VLOOKUP(A201,sales_weekly_agg!$A$5:$B$98,2,FALSE),"") | D201: =IF(C201="","",C201-B201)
A202: 45593 | B202: 71 | C202: =_xlfn.IFNA(VLOOKUP(A202,sales_weekly_agg!$A$5:$B$98,2,FALSE),"") | D202: =IF(C202="","",C202-B202)
A203: 45600 | B203: 56 | C203: =_xlfn.IFNA(VLOOKUP(A203,sales_weekly_agg!$A$5:$B$98,2,FALSE),"") | D203: =IF(C203="","",C203-B203)
A204: 45607 | B204: 59 | C204: =_xlfn.IFNA(VLOOKUP(A204,sales_weekly_agg!$A$5:$B$98,2,FALSE),"") | D204: =IF(C204="","",C204-B204)
A205: 45614 | B205: 58 | C205: =_xlfn.IFNA(VLOOKUP(A205,sales_weekly_agg!$A$5:$B$98,2,FALSE),"") | D205: =IF(C205="","",C205-B205)
A206: 45621 | B206: 55 | C206: =_xlfn.IFNA(VLOOKUP(A206,sales_weekly_agg!$A$5:$B$98,2,FALSE),"") | D206: =IF(C206="","",C206-B206)
...

Sheet module_3_design
A1: Business Problem
A2: Quantify the revenue and margin impact of persistent demand–supply misalignment at a weekly trend level, distinguishing episodic execution noise from systematic planning bias.
A4: Data Grain
A5: All Module 3 analysis is performed at a Trend × Week level and aggregated only after financial impact is computed.
A7: Aggregation Rule
A8: Financial impact is computed at a weekly trend level and aggregated using sum of losses and max run length, rather than averages, to preserve risk magnitude and persistence severity.
A10: Column Name
A11: week_start_date
A12: trend_key
A13: demand_index
A14: units_sold
A15: gap_units
... A62: Estimated opportunity loss computed by applying average selling price to relative unmet demand signals. Values represent comparative financial exposure across trends, not realized or forecasted revenue.

Sheet trend_week_facts
A1: week_start_date | B1: trend_key | C1: demand_index | D1: units_sold | E1: gap_units | F1: gap_sign | G1: persistence_flag | H1: run_id | I1: run_length | J1: asp | K1: lost_revenue | L1: markdown_loss | M1: total_financial_impact | N1: cumulative_financial_impact
A2: 44921 | B2: sportswear | C2: 28 | D2: 0 | E2: -28 | F2: -1 | H2: 1 | J2: =IF(B2="sportswear",1500, IF(B2="cargo_pants",2000,"")) -> 1500 | K2: =IF(F2=-1, ABS(E2)*J2, 0) -> 42000 | L2: =IF(F2=1, E2*J2*0.3, 0) -> 0 | M2: =K2+L2 -> 42000 | N2: 42000
A3: 44928 | B3: sportswear | C3: 29 | D3: 25 | E3: -4 | F3: -1 | G3: 1 | H3: =IF(F3=F2,H2,H2+1) -> 1 | I3: 1 | J3: =IF(B3="sportswear",1500, IF(B3="cargo_pants",2000,"")) -> 1500 | K3: =IF(F3=-1, ABS(E3)*J3, 0) -> 6000 | L3: =IF(F3=1, E3*J3*0.3, 0) -> 0 | M3: =K3+L3 -> 6000 | N3: =N2+M3 -> 48000
A4: 44935 | B4: sportswear | C4: 28 | D4: 38 | E4: 10 | F4: 1 | G4: 0 | H4: =IF(F4=F3,H3,H3+1) -> 2 | I4: =IF(H3=H4,I3+1,1) -> 1 | J4: =IF(B4="sportswear",1500, IF(B4="cargo_pants",2000,"")) -> 1500 | K4: =IF(F4=-1, ABS(E4)*J4, 0) -> 0 | L4: =IF(F4=1, E4*J4*0.3, 0) -> 4500 | M4: =K4+L4 -> 4500 | N4: =N3+M4 -> 52500
A5: 44942 | B5: sportswear | C5: 28 | D5: 20 | E5: -8 | F5: -1 | G5: 0 | H5: =IF(F5=F4,H4,H4+1) -> 3 | I5: =IF(H4=H5,I4+1,1) -> 1 | J5: =IF(B5="sportswear",1500, IF(B5="cargo_pants",2000,"")) -> 1500 | K5: =IF(F5=-1, ABS(E5)*J5, 0) -> 12000 | L5: =IF(F5=1, E5*J5*0.3, 0) -> 0 | M5: =K5+L5 -> 12000 | N5: =N4+M5 -> 64500
A6: 44949 | B6: sportswear | C6: 28 | D6: 33 | E6: 5 | F6: 1 | G6: 0 | H6: =IF(F6=F5,H5,H5+1) -> 4 | I6: =IF(H5=H6,I5+1,1) -> 1 | J6: =IF(B6="sportswear",1500, IF(B6="cargo_pants",2000,"")) -> 1500 | K6: =IF(F6=-1, ABS(E6)*J6, 0) -> 0 | L6: =IF(F6=1, E6*J6*0.3, 0) -> 2250 | M6: =K6+L6 -> 2250 | N6: =N5+M6 -> 66750
A7: 44956 | B7: sportswear | C7: 27 | D7: 27 | E7: 0 | F7: 0 | G7: 0 | H7: =IF(F7=F6,H6,H6+1) -> 5 | I7: =IF(H6=H7,I6+1,1) -> 1 | J7: =IF(B7="sportswear",1500, IF(B7="cargo_pants",2000,"")) -> 1500 | K7: =IF(F7=-1, ABS(E7)*J7, 0) -> 0 | L7: =IF(F7=1, E7*J7*0.3, 0) -> 0 | M7: =K7+L7 -> 0 | N7: =N6+M7 -> 66750
A8: 44963 | B8: sportswear | C8: 26 | D8: 28 | E8: 2 | F8: 1 | G8: 0 | H8: =IF(F8=F7,H7,H7+1) -> 6 | I8: =IF(H7=H8,I7+1,1) -> 1 | J8: =IF(B8="sportswear",1500, IF(B8="cargo_pants",2000,"")) -> 1500 | K8: =IF(F8=-1, ABS(E8)*J8, 0) -> 0 | L8: =IF(F8=1, E8*J8*0.3, 0) -> 900 | M8: =K8+L8 -> 900 | N8: =N7+M8 -> 67650
A9: 44970 | B9: sportswear | C9: 25 | D9: 19 | E9: -6 | F9: -1 | G9: 0 | H9: =IF(F9=F8,H8,H8+1) -> 7 | I9: =IF(H8=H9,I8+1,1) -> 1 | J9: =IF(B9="sportswear",1500, IF(B9="cargo_pants",2000,"")) -> 1500 | K9: =IF(F9=-1, ABS(E9)*J9, 0) -> 9000 | L9: =IF(F9=1, E9*J9*0.3, 0) -> 0 | M9: =K9+L9 -> 9000 | N9: =N8+M9 -> 76650
A10: 44977 | B10: sportswear | C10: 28 | D10: 28 | E10: 0 | F10: 0 | G10: 0 | H10: =IF(F10=F9,H9,H9+1) -> 8 | I10: =IF(H9=H10,I9+1,1) -> 1 | J10: =IF(B10="sportswear",1500, IF(B10="cargo_pants",2000,"")) -> 1500 | K10: =IF(F10=-1, ABS(E10)*J10, 0) -> 0 | L10: =IF(F10=1, E10*J10*0.3, 0) -> 0 | M10: =K10+L10 -> 0 | N10: =N9+M10 -> 76650
A11: 44984 | B11: sportswear | C11: 29 | D11: 31 | E11: 2 | F11: 1 | G11: 0 | H11: =IF(F11=F10,H10,H10+1) -> 9 | I11: =IF(H10=H11,I10+1,1) -> 1 | J11: =IF(B11="sportswear",1500, IF(B11="cargo_pants",2000,"")) -> 1500 | K11: =IF(F11=-1, ABS(E11)*J11, 0) -> 0 | L11: =IF(F11=1, E11*J11*0.3, 0) -> 900 | M11: =K11+L11 -> 900 | N11: =N10+M11 -> 77550
A12: 44991 | B12: sportswear | C12: 30 | D12: 21 | E12: -9 | F12: -1 | G12: 0 | H12: =IF(F12=F11,H11,H11+1) -> 10 | I12: =IF(H11=H12,I11+1,1) -> 1 | J12: =IF(B12="sportswear",1500, IF(B12="cargo_pants",2000,"")) -> 1500 | K12: =IF(F12=-1, ABS(E12)*J12, 0) -> 13500 | L12: =IF(F12=1, E12*J12*0.3, 0) -> 0 | M12: =K12+L12 -> 13500 | N12: =N11+M12 -> 91050
A13: 44998 | B13: sportswear | C13: 29 | D13: 34 | E13: 5 | F13: 1 | G13: 0 | H13: =IF(F13=F12,H12,H12+1) -> 11 | I13: =IF(H12=H13,I12+1,1) -> 1 | J13: =IF(B13="sportswear",1500, IF(B13="cargo_pants",2000,"")) -> 1500 | K13: =IF(F13=-1, ABS(E13)*J13, 0) -> 0 | L13: =IF(F13=1, E13*J13*0.3, 0) -> 2250 | M13: =K13+L13 -> 2250 | N13: =N12+M13 -> 93300
A14: 45005 | B14: sportswear | C14: 29 | D14: 29 | E14: 0 | F14: 0 | G14: 0 | H14: =IF(F14=F13,H13,H13+1) -> 12 | I14: =IF(H13=H14,I13+1,1) -> 1 | J14: =IF(B14="sportswear",1500, IF(B14="cargo_pants",2000,"")) -> 1500 | K14: =IF(F14=-1, ABS(E14)*J14, 0) -> 0 | L14: =IF(F14=1, E14*J14*0.3, 0) -> 0 | M14: =K14+L14 -> 0 | N14: =N13+M14 -> 93300
A15: 45012 | B15: sportswear | C15: 29 | D15: 15 | E15: -14 | F15: -1 | G15: 0 | H15: =IF(F15=F14,H14,H14+1) -> 13 | I15: =IF(H14=H15,I14+1,1) -> 1 | J15: =IF(B15="sportswear",1500, IF(B15="cargo_pants",2000,"")) -> 1500 | K15: =IF(F15=-1, ABS(E15)*J15, 0) -> 21000 | L15: =IF(F15=1, E15*J15*0.3, 0) -> 0 | M15: =K15+L15 -> 21000 | N15: =N14+M15 -> 114300
... A95: 45572 | B95: sportswear | C95: 31 | D95: 31 | E95: 0 | F95: 0 | G95: 0 | H95: =IF(F95=F94,H94,H94+1) -> 52 | I95: =IF(H94=H95,I94+1,1) -> 1 | J95: =IF(B95="sportswear",1500, IF(B95="cargo_pants",2000,"")) -> 1500 | K95: =IF(F95=-1, ABS(E95)*J95, 0) -> 0 | L95: =IF(F95=1, E95*J95*0.3, 0) -> 0 | M95: =K95+L95 -> 0 | N95: =N94+M95 -> 812100
A96: 44921 | B96: cargo_pants | C96: 38 | D96: 3 | E96: =IF(D96="","",D96-C96) -> -35 | F96: =_xlfn.IFS(E96>0,1,E96<0,-1,E96=0,0) -> -1 | H96: 1 | J96: =IF(B96="sportswear",1500, IF(B96="cargo_pants",2000,"")) -> 2000 | K96: =IF(F96=-1, ABS(E96)*J96, 0) -> 70000 | L96: =IF(F96=1, E96*J96*0.3, 0) -> 0 | M96: =K96+L96 -> 70000 | N96: 70000
A97: 44928 | B97: cargo_pants | C97: 37 | D97: 19 | E97: =IF(D97="","",D97-C97) -> -18 | F97: =_xlfn.IFS(E97>0,1,E97<0,-1,E97=0,0) -> -1 | G97: 1 | H97: =IF(F97=F96,H96,H96+1) -> 1 | I97: 1 | J97: =IF(B97="sportswear",1500, IF(B97="cargo_pants",2000,"")) -> 2000 | K97: =IF(F97=-1, ABS(E97)*J97, 0) -> 36000 | L97: =IF(F97=1, E97*J97*0.3, 0) -> 0 | M97: =K97+L97 -> 36000 | N97: =N96+M97 -> 106000
A98: 44935 | B98: cargo_pants | C98: 40 | D98: 19 | E98: =IF(D98="","",D98-C98) -> -21 | F98: =_xlfn.IFS(E98>0,1,E98<0,-1,E98=0,0) -> -1 | G98: 1 | H98: =IF(F98=F97,H97,H97+1) -> 1 | I98: =IF(H97=H98,I97+1,1) -> 2 | J98: =IF(B98="sportswear",1500, IF(B98="cargo_pants",2000,"")) -> 2000 | K98: =IF(F98=-1, ABS(E98)*J98, 0) -> 42000 | L98: =IF(F98=1, E98*J98*0.3, 0) -> 0 | M98: =K98+L98 -> 42000 | N98: =N97+M98 -> 148000
A99: 44942 | B99: cargo_pants | C99: 38 | D99: 27 | E99: =IF(D99="","",D99-C99) -> -11 | F99: =_xlfn.IFS(E99>0,1,E99<0,-1,E99=0,0) -> -1 | G99: 1 | H99: =IF(F99=F98,H98,H98+1) -> 1 | I99: =IF(H98=H99,I98+1,1) -> 3 | J99: =IF(B99="sportswear",1500, IF(B99="cargo_pants",2000,"")) -> 2000 | K99: =IF(F99=-1, ABS(E99)*J99, 0) -> 22000 | L99: =IF(F99=1, E99*J99*0.3, 0) -> 0 | M99: =K99+L99 -> 22000 | N99: =N98+M99 -> 170000
A100: 44949 | B100: cargo_pants | C100: 43 | D100: 35 | E100: =IF(D100="","",D100-C100) -> -8 | F100: =_xlfn.IFS(E100>0,1,E100<0,-1,E100=0,0) -> -1 | G100: 1 | H100: =IF(F100=F99,H99,H99+1) -> 1 | I100: =IF(H99=H100,I99+1,1) -> 4 | J100: =IF(B100="sportswear",1500, IF(B100="cargo_pants",2000,"")) -> 2000 | K100: =IF(F100=-1, ABS(E100)*J100, 0) -> 16000 | L100: =IF(F100=1, E100*J100*0.3, 0) -> 0 | M100: =K100+L100 -> 16000 | N100: =N99+M100 -> 186000
A101: 44956 | B101: cargo_pants | C101: 41 | D101: 35 | E101: =IF(D101="","",D101-C101) -> -6 | F101: =_xlfn.IFS(E101>0,1,E101<0,-1,E101=0,0) -> -1 | G101: 1 | H101: =IF(F101=F100,H100,H100+1) -> 1 | I101: =IF(H100=H101,I100+1,1) -> 5 | J101: =IF(B101="sportswear",1500, IF(B101="cargo_pants",2000,"")) -> 2000 | K101: =IF(F101=-1, ABS(E101)*J101, 0) -> 12000 | L101: =IF(F101=1, E101*J101*0.3, 0) -> 0 | M101: =K101+L101 -> 12000 | N101: =N100+M101 -> 198000
A102: 44963 | B102: cargo_pants | C102: 43 | D102: 31 | E102: =IF(D102="","",D102-C102) -> -12 | F102: =_xlfn.IFS(E102>0,1,E102<0,-1,E102=0,0) -> -1 | G102: 1 | H102: =IF(F102=F101,H101,H101+1) -> 1 | I102: =IF(H101=H102,I101+1,1) -> 6 | J102: =IF(B102="sportswear",1500, IF(B102="cargo_pants",2000,"")) -> 2000 | K102: =IF(F102=-1, ABS(E102)*J102, 0) -> 24000 | L102: =IF(F102=1, E102*J102*0.3, 0) -> 0 | M102: =K102+L102 -> 24000 | N102: =N101+M102 -> 222000
A103: 44970 | B103: cargo_pants | C103: 43 | D103: 31 | E103: =IF(D103="","",D103-C103) -> -12 | F103: =_xlfn.IFS(E103>0,1,E103<0,-1,E103=0,0) -> -1 | G103: 1 | H103: =IF(F103=F102,H102,H102+1) -> 1 | I103: =IF(H102=H103,I102+1,1) -> 7 | J103: =IF(B103="sportswear",1500, IF(B103="cargo_pants",2000,"")) -> 2000 | K103: =IF(F103=-1, ABS(E103)*J103, 0) -> 24000 | L103: =IF(F103=1, E103*J103*0.3, 0) -> 0 | M103: =K103+L103 -> 24000 | N103: =N102+M103 -> 246000
A104: 44977 | B104: cargo_pants | C104: 49 | D104: 37 | E104: =IF(D104="","",D104-C104) -> -12 | F104: =_xlfn.IFS(E104>0,1,E104<0,-1,E104=0,0) -> -1 | G104: 1 | H104: =IF(F104=F103,H103,H103+1) -> 1 | I104: =IF(H103=H104,I103+1,1) -> 8 | J104: =IF(B104="sportswear",1500, IF(B104="cargo_pants",2000,"")) -> 2000 | K104: =IF(F104=-1, ABS(E104)*J104, 0) -> 24000 | L104: =IF(F104=1, E104*J104*0.3, 0) -> 0 | M104: =K104+L104 -> 24000 | N104: =N103+M104 -> 270000
A105: 44984 | B105: cargo_pants | C105: 45 | D105: 29 | E105: =IF(D105="","",D105-C105) -> -16 | F105: =_xlfn.IFS(E105>0,1,E105<0,-1,E105=0,0) -> -1 | G105: 1 | H105: =IF(F105=F104,H104,H104+1) -> 1 | I105: =IF(H104=H105,I104+1,1) -> 9 | J105: =IF(B105="sportswear",1500, IF(B105="cargo_pants",2000,"")) -> 2000 | K105: =IF(F105=-1, ABS(E105)*J105, 0) -> 32000 | L105: =IF(F105=1, E105*J105*0.3, 0) -> 0 | M105: =K105+L105 -> 32000 | N105: =N104+M105 -> 302000
A106: 44991 | B106: cargo_pants | C106: 48 | D106: 33 | E106: =IF(D106="","",D106-C106) -> -15 | F106: =_xlfn.IFS(E106>0,1,E106<0,-1,E106=0,0) -> -1 | G106: 1 | H106: =IF(F106=F105,H105,H105+1) -> 1 | I106: =IF(H105=H106,I105+1,1) -> 10 | J106: =IF(B106="sportswear",1500, IF(B106="cargo_pants",2000,"")) -> 2000 | K106: =IF(F106=-1, ABS(E106)*J106, 0) -> 30000 | L106: =IF(F106=1, E106*J106*0.3, 0) -> 0 | M106: =K106+L106 -> 30000 | N106: =N105+M106 -> 332000
A107: 44998 | B107: cargo_pants | C107: 46 | D107: 31 | E107: =IF(D107="","",D107-C107) -> -15 | F107: =_xlfn.IFS(E107>0,1,E107<0,-1,E107=0,0) -> -1 | G107: 1 | H107: =IF(F107=F106,H106,H106+1) -> 1 | I107: =IF(H106=H107,I106+1,1) -> 11 | J107: =IF(B107="sportswear",1500, IF(B107="cargo_pants",2000,"")) -> 2000 | K107: =IF(F107=-1, ABS(E107)*J107, 0) -> 30000 | L107: =IF(F107=1, E107*J107*0.3, 0) -> 0 | M107: =K107+L107 -> 30000 | N107: =N106+M107 -> 362000
A108: 45005 | B108: cargo_pants | C108: 50 | D108: 21 | E108: =IF(D108="","",D108-C108) -> -29 | F108: =_xlfn.IFS(E108>0,1,E108<0,-1,E108=0,0) -> -1 | G108: 1 | H108: =IF(F108=F107,H107,H107+1) -> 1 | I108: =IF(H107=H108,I107+1,1) -> 12 | J108: =IF(B108="sportswear",1500, IF(B108="cargo_pants",2000,"")) -> 2000 | K108: =IF(F108=-1, ABS(E108)*J108, 0) -> 58000 | L108: =IF(F108=1, E108*J108*0.3, 0) -> 0 | M108: =K108+L108 -> 58000 | N108: =N107+M108 -> 420000
A109: 45012 | B109: cargo_pants | C109: 50 | D109: 18 | E109: =IF(D109="","",D109-C109) -> -32 | F109: =_xlfn.IFS(E109>0,1,E109<0,-1,E109=0,0) -> -1 | G109: 1 | H109: =IF(F109=F108,H108,H108+1) -> 1 | I109: =IF(H108=H109,I108+1,1) -> 13 | J109: =IF(B109="sportswear",1500, IF(B109="cargo_pants",2000,"")) -> 2000 | K109: =IF(F109=-1, ABS(E109)*J109, 0) -> 64000 | L109: =IF(F109=1, E109*J109*0.3, 0) -> 0 | M109: =K109+L109 -> 64000 | N109: =N108+M109 -> 484000
... A189: 45572 | B189: cargo_pants | C189: 68 | D189: 22 | E189: =IF(D189="","",D189-C189) -> -46 | F189: =_xlfn.IFS(E189>0,1,E189<0,-1,E189=0,0) -> -1 | G189: 1 | H189: =IF(F189=F188,H188,H188+1) -> 1 | I189: =IF(H188=H189,I188+1,1) -> 93 | J189: =IF(B189="sportswear",1500, IF(B189="cargo_pants",2000,"")) -> 2000 | K189: =IF(F189=-1, ABS(E189)*J189, 0) -> 92000 | L189: =IF(F189=1, E189*J189*0.3, 0) -> 0 | M189: =K189+L189 -> 92000 | N189: =N188+M189 -> 6202000

Sheet module_3_metrics
A1: trend_key | B1: total_lost_revenue | C1: total_markdown_loss | D1: max_run_length | E1: persistence_rate
A2: sportswear | B2: =SUM(trend_week_facts!K2:K95) -> 732000 | C2: =SUM(trend_week_facts!L2:L95) -> 80100 | D2: =MAX(trend_week_facts!I3:I95) -> 9 | E2: =SUM(trend_week_facts!G3:G95)/COUNT(trend_week_facts!G3:G95) -> 0.4516129
A3: cargo_pants | B3: =SUM(trend_week_facts!K96:K189) -> 6202000 | C3: =SUM(trend_week_facts!L96:L189) -> 0 | D3: =MAX(trend_week_facts!I97:I189) -> 93 | E3: =SUM(trend_week_facts!G97:G189)/COUNT(trend_week_facts!G97:G189) -> 1

Sheet final_outputs
A1: trend_key | B1: risk_type | C1: primary_driver | D1: business_action
A2: sportswear | B2: Execution volatility | C2: Ops / allocation noise | D2: Improve fulfillment stability
A3: cargo_pants | B3: Structural revenue loss | C3: Planning bias | D3: Rebuild demand planning logic
A6: “Cargo Pants generated over 8× the lost revenue of Sportswear despite lower sales volatility. This loss was not episodic but persistent across 93 consecutive weeks, indicating structural demand suppression rather than execution noise.”
A8: week_start_date | B8: sportswear_cum_fin_impact | C8: cargo_pants_cum_fin_impact
A9: 44921 | B9: 42000 | C9: 70000
A10: 44928 | B10: 48000 | C10: =C9+B10 -> 118000
A11: 44935 | B11: 52500 | C11: =C10+B11 -> 170500
A12: 44942 | B12: 64500 | C12: =C11+B12 -> 235000
A13: 44949 | B13: 66750 | C13: =C12+B13 -> 301750
A14: 44956 | B14: 66750 | C14: =C13+B14 -> 368500
A15: 44963 | B15: 67650 | C15: =C14+B15 -> 436150
A16: 44970 | B16: 76650 | C16: =C15+B16 -> 512800
A17: 44977 | B17: 76650 | C17: =C16+B17 -> 589450
A18: 44984 | B18: 77550 | C18: =C17+B18 -> 667000
A19: 44991 | B19: 91050 | C19: =C18+B19 -> 758050
A20: 44998 | B20: 93300 | C20: =C19+B20 -> 851350
A21: 45005 | B21: 93300 | C21: =C20+B21 -> 944650
... A102: 45572 | B102: 812100 | C102: =C101+B102 -> 36471250
